11:45:02.269 [INFO] MainThread: Starting Communicatorâ€¦ PUB=tcp://127.0.0.1:5556 REP=tcp://127.0.0.1:5557
11:45:02.269 [INFO] RX: Serial connected: /dev/pts/4 @ 115200
11:51:42.887 [WARNING] RX: RX loop error: device reports readiness to read but returned no data (device disconnected or multiple access on port?)
Traceback (most recent call last):
  File "/home/jarred/git/timone-ground-station/TimoneGUI/tools/communicator.py", line 417, in _rx_loop
    frame = self._framer.read_frame_blocking(timeout_s=1.0)
  File "/home/jarred/git/timone-ground-station/TimoneGUI/tools/communicator.py", line 271, in read_frame_blocking
    b = self.ser.read(1)
  File "/home/jarred/.local/lib/python3.10/site-packages/serial/serialposix.py", line 595, in read
    raise SerialException(
serial.serialutil.SerialException: device reports readiness to read but returned no data (device disconnected or multiple access on port?)
11:51:43.388 [WARNING] RX: RX loop error: [Errno 2] could not open port /dev/pts/4: [Errno 2] No such file or directory: '/dev/pts/4'
Traceback (most recent call last):
  File "/home/jarred/.local/lib/python3.10/site-packages/serial/serialposix.py", line 322, in open
    self.fd = os.open(self.portstr, os.O_RDWR | os.O_NOCTTY | os.O_NONBLOCK)
FileNotFoundError: [Errno 2] No such file or directory: '/dev/pts/4'

During handling of the above exception, another exception occurred:

Traceback (most recent call last):
  File "/home/jarred/git/timone-ground-station/TimoneGUI/tools/communicator.py", line 413, in _rx_loop
    self._connect_serial()
  File "/home/jarred/git/timone-ground-station/TimoneGUI/tools/communicator.py", line 385, in _connect_serial
    ser = serial.Serial(
  File "/home/jarred/.local/lib/python3.10/site-packages/serial/serialutil.py", line 244, in __init__
    self.open()
  File "/home/jarred/.local/lib/python3.10/site-packages/serial/serialposix.py", line 325, in open
    raise SerialException(msg.errno, "could not open port {}: {}".format(self._port, msg))
serial.serialutil.SerialException: [Errno 2] could not open port /dev/pts/4: [Errno 2] No such file or directory: '/dev/pts/4'
